Namespace(batch_size=19, beta1=0.5, cuda_device=0, d_activation=19, d_funit=19, d_loss_function='MSE', d_lr=0.0003, d_model_path=None, d_network='Hul112Disc', d_weights_dict_path=None, g_activation=19, g_funit=19, g_lr=0.0003, g_model_path=None, g_network='Hul128Net', g_weights_dict_path=None, min_lr=5e-08, not_conditional=False, test_reserve=None, threads=8, time_limit=172800, train_data=None, weight_L1=0.05, weight_SSIM=0.2)
cmd: python3 gan_train.py
Error: generator network not properly specified
